<robot name="jmbot" xmlns:xacro="http://ros.org/wiki/xacro">

<!-- Link ficticio anclado al mundo -->
<!-- Joint fijo que ancla 'base' al suelo -->
  <link name="world"/>
  <joint name="world_joint" type="fixed">
      <parent link="world"/>
      <child link="base"/>
      <origin rpy="0.0 0.0 0.0" xyz="0.0 0.0 0.0"/>
  </joint>

  <link name="base">
  <gazebo reference="base">
  </gazebo>
    <visual>
      <geometry>    
        <mesh filename="package://jmbot/urdf/meshes/Base_base.obj"/>
      </geometry>
      <material name="blue">
        <color rgba="0.0 0.0 1.0 1"/>
      </material>
    </visual>
    <collision>
      <geometry>
        <mesh filename="package://jmbot/urdf/meshes/Base_base.stl"/>
      </geometry>
    </collision>
    <inertial>
      <mass value="1"/>
     <inertia ixx="0.0043125" ixy="0" ixz="0" iyy="0.0043125" iyz="0" izz="0.0075"/>
    </inertial>
  </link>

  <joint name="Base_base" type="revolute">
    <parent link="base"/>
    <child link="Ensamblaje_base"/>
    <origin xyz="0 0 0" rpy="0 0 0"/>
    <axis xyz="0 0 1"/>
    <limit lower="-3.14" upper="3.14" effort="1000000000" velocity="100"/>
    <dynamics damping="0.1"/>
  </joint>

  <!-- Ensamblaje_base -->
  <link name="Ensamblaje_base">
    <visual>
      <geometry>
        <mesh filename="package://jmbot/urdf/meshes/Ensamblaje_base_fix.obj"/>
      </geometry>
      <material name="pink">
        <color rgba="1.0 0.4 0.7 1"/>
      </material>
    </visual>
    <collision>
      <geometry>
        <mesh filename="package://jmbot/urdf/meshes/Ensamblaje_base_fix.stl"/>
      </geometry>
    </collision>
    <inertial>
      <mass value="0.7"/>
      <inertia ixx="0.0117" ixy="0" ixz="0" iyy="0.0177" iyz="0" izz="0.01"/>
    </inertial>
  </link>

  <joint name="Base_hombro" type="revolute">
    <parent link="Ensamblaje_base"/>
    <child link="hombro"/>
    <origin xyz="0 0 14" rpy="0 0 0"/>
    <axis xyz="1 0 0"/>
    <limit lower="-3.14" upper="3.14" effort="10000000000" velocity="100"/>
    <dynamics damping="0.01" friction="0.0"/>
  </joint>

  <!-- Hombro -->
  <link name="hombro">
    <visual>
      <geometry>
        <mesh filename="package://jmbot/urdf/meshes/Hombro_pos_prueba.obj"/>
      </geometry>
      <material name="red">
        <color rgba="1.0 0.0 0.0 1"/>
      </material>
    </visual>
    <collision>
      <geometry>
        <mesh filename="package://jmbot/urdf/meshes/Hombro_pos_prueba.stl"/>
      </geometry>
    </collision>
    <inertial>
      <mass value="0.2"/>
      <inertia ixx="0.0034" ixy="0" ixz="0" iyy="0.0032" iyz="0" izz="0.0004"/>
    </inertial>
  </link>

  <joint name="Hombro_medio" type="revolute">
    <parent link="hombro"/>
    <child link="brazomedio"/>
    <origin xyz="0 0 11" rpy="0 0 0"/>
    <axis xyz="1 0 0"/>
    <limit lower="-3.14" upper="3.14" effort="10000000000" velocity="100"/>
    <dynamics damping="0.1"/>
  </joint>

  <!-- Brazomedio -->
  <link name="brazomedio">
    <visual>
      <geometry>
        <mesh filename="package://jmbot/urdf/meshes/brazomedio.obj"/>
      </geometry>
      <material name="green">
        <color rgba="0.0 1.0 0.0 1"/>
      </material>
    </visual>
    <collision>
      <geometry>
        <mesh filename="package://jmbot/urdf/meshes/brazomedio.stl"/>
      </geometry>
    </collision>
    <inertial>
      <mass value="0.1"/>
      <inertia ixx="0.0076" ixy="0" ixz="0" iyy="0.0076" iyz="0" izz="0.00027"/>
    </inertial>
  </link>

  <joint name="UNION_MUNECA" type="revolute">
    <parent link="brazomedio"/>
    <child link="UNION"/>
    <origin xyz="0 13.5 0" rpy="0 0 0"/>
    <axis xyz="1 0 0"/>
    <limit lower="-3.14" upper="3.14" effort="1000000000" velocity="100"/>
    <dynamics damping="0.1"/>
  </joint>

  <!-- UNION -->
  <link name="UNION">
    <visual>
      <geometry>
        <mesh filename="package://jmbot/urdf/meshes/UNION.obj"/>
      </geometry>
      <material name="blue2">
        <color rgba="0.0 0.0 1.0 1"/>
      </material>
    </visual>
    <collision>
      <geometry>
        <mesh filename="package://jmbot/urdf/meshes/UNION.stl"/>
      </geometry>
    </collision>
    <inertial>
      <mass value="0.05"/>
      <inertia ixx="0.00045" ixy="0" ixz="0" iyy="0.00047" iyz="0" izz="0.00019"/>
    </inertial>
  </link>

  <joint name="muneca_pinza" type="revolute">
    <parent link="UNION"/>
    <child link="pinza"/>
    <origin xyz="0 0 0" rpy="0 0 0"/>
    <axis xyz="0 1 0"/>
    <limit lower="-3.14" upper="3.14" effort="10000000000" velocity="100"/>
    <dynamics damping="0.1"/>
  </joint>

  <!-- Pinza -->
  <link name="pinza">
    <visual>
      <geometry>
        <mesh filename="package://jmbot/urdf/meshes/Pinza_base_cambio.obj"/>
      </geometry>
      <material name="pink2">
        <color rgba="1.0 0.4 0.7 1"/>
      </material>
    </visual>
    <collision>
      <geometry>
        <mesh filename="package://jmbot/urdf/meshes/Pinza_base_cambio.stl"/>
      </geometry>
    </collision>
    <inertial>
      <mass value="0.01"/>
      <inertia ixx="0.00049" ixy="0" ixz="0" iyy="0.00047" iyz="0" izz="0.00019"/>
    </inertial>
  </link>


 <joint name="pinza_final" type="revolute">
    <parent link="pinza"/>
    <child link="pinza_extremo"/>
    <origin xyz="0 0 0" rpy="0 0 0"/>
    <axis xyz="0 0 1"/>
    <limit lower="-3.14" upper="3.14" effort="10000000000" velocity="100"/>
    <dynamics damping="0.1"/>
  </joint>

  <!-- Pinza -->
  <link name="pinza_extremo">
    <visual>
      <geometry>
        <mesh filename="package://jmbot/urdf/meshes/Pinza_cambio.obj"/>
      </geometry>
      <material name="red">
        <color rgba="1.0 0.0 0.0 1"/>
      </material>
    </visual>
    <collision>
      <geometry>
        <mesh filename="package://jmbot/urdf/meshes/Pinza_cambio.stl"/>
      </geometry>
    </collision>
    <inertial>
      <mass value="0.01"/>
      <inertia ixx="0.00049" ixy="0" ixz="0" iyy="0.00047" iyz="0" izz="0.00019"/>
    </inertial>
  </link>
  <!-- Añadir plugin de ROS Control -->

 <ros2_control name="GazeboSimSystem" type="system">
  <hardware>
    <plugin>gz_ros2_control/GazeboSimSystem</plugin>
  </hardware>
  <joint name="Base_base">
    <command_interface name="position"/>
    <state_interface name="position"/>
  </joint>
  <joint name="Base_hombro">
    <command_interface name="position"/>
    <state_interface name="position"/>
  </joint>
  <joint name="Hombro_medio">
    <command_interface name="position"/>
    <state_interface name="position"/>
  </joint>
  <joint name="UNION_MUNECA">
    <command_interface name="position"/>
    <state_interface name="position"/>
  </joint>
  <joint name="muneca_pinza">
    <command_interface name="position"/>
    <state_interface name="position"/>
  </joint>
  <joint name="pinza_final">
    <command_interface name="position"/>
    <state_interface name="position"/>
  </joint>
</ros2_control>

<gazebo>
  <plugin filename="libgz_ros2_control-system.so" name="gz_ros2_control::GazeboSimROS2ControlPlugin">
    <parameters>$(find jmbot)/config/controller.yaml</parameters>
    <controller_manager_prefix_node_name>controller_manager</controller_manager_prefix_node_name>
  </plugin>
</gazebo>
<gazebo reference="world_link">
  <static>true</static>
</gazebo>
</robot>
